Workbook

Sheet About
D1: Declaration of AI Assistance: All data modeling, functions, and analytical logic within these Excel projects were developed independently. Generative AI tools (ChatGPT and Gemini) were utilized solely to enhance syntax, tone, and readability of textual elements.
B2: RMC Costing, Pricing & Profitability Model
B3: A commercial-finance decision model for a ready-mix concrete operation.
B5: ⚠ ILLUSTRATIVE / SAMPLE DATA — built to demonstrate methodology. All rates and figures are fictional and do not represent any real company or client.
B7: WHAT THIS MODEL DOES
B8: • Inputs all the rates in one place (materials, diesel, electricity, labour, transport, pumping, repairs) plus monthly fixed costs. Change an input and the whole model updates.
B9: • Mix Design material quantity per CBM for each grade (M10–M40); material cost = qty × rate.
B10: • Costing splits variable vs fixed/semi-fixed cost, then works out cost/CBM, markup, selling price, contribution and gross margin per grade.
B11: • Scenarios shock inputs (cement +10%, diesel +10%, transport +15%, price −5%, volume −20%) driving Base / Downside / Upside on the M25 reference grade.
B12: • Profitability grade-wise monthly P&L: Revenue → Variable → Contribution → Fixed → EBITDA → Interest → PBT → margin %.
B13: • Dashboard answers key management questions: most profitable grade, break-even volume, required price for a target gross margin, cement-cost sensitivity, major cost drivers, and scenario range.
B15: SKILLS DEMONSTRATED
B16: Cost accounting · Marginal costing & contribution analysis · Break-even & CVP · Cost-plus pricing · Margin vs markup analysis · Sensitivity / scenario modelling · Product-line profitability · Advanced Excel (cross-sheet formulas, INDEX/MATCH, charts) · Management accounting
B18: Built by Akhila Nayak · Accountant · R2R, MIS & Cost Analysis

Sheet Dashboard
B2: RMC Costing, Pricing & Profitability Dashboard
B3: Ready-Mix Concrete · 7 grades (M10–M40) · 4,000 CBM/month · Illustrative data (INR)
B5: MONTHLY REVENUE | E5: MONTHLY PBT | H5: BLENDED MARGIN | K5: TOTAL VOLUME
B6: =Profitability!E13 -> 27908091 | E6: =Profitability!K13 -> 3400185.7 | H6: =Profitability!L13 -> 0.12183513 | K6: =Profitability!C13 -> 4000
B14: MOST PROFITABLE GRADE (by monthly PBT) | F14: MANAGEMENT QUESTIONS
B15: Grade | C15: PBT (₹) | D15: Margin % | F15: Best contribution/CBM grade | I15: =INDEX(Costing!B6:B12,MATCH(MAX(Costing!M6:M12),Costing!M6:M12,0)) -> M40
B16: =Profitability!B6 -> M10 | C16: =Profitability!K6 -> 209205 | D16: =Profitability!L6 -> 0.12010127 | F16: Break-even volume — M25 equiv (CBM) | I16: =(Inputs!C30-Inputs!C28)/INDEX(Costing!M6:M12,4) -> 1179.359
B17: =Profitability!B7 -> M15 | C17: =Profitability!K7 -> 453330 | D17: =Profitability!L7 -> 0.1208387 | F17: M25 price for 10% gross margin | I17: =Costing!J9/(1-0.1) -> 6909.2778
B18: =Profitability!B8 -> M20 | C18: =Profitability!K8 -> 907632 | D18: =Profitability!L8 -> 0.12159295 | F18: Cement +10% → M25 cost/CBM | I18: =Costing!J9+'Mix Design'!C9*Inputs!D7*0.1 -> 6491.95
B19: =Profitability!B9 -> M25 | C19: =Profitability!K9 -> 785477.25 | D19: =Profitability!L9 -> 0.12204447 | F19: Largest M25 cost component | I19: =INDEX(F29:F34,MATCH(MAX(G29:G34),G29:G34,0)) -> Cement
B20: =Profitability!B10 -> M30 | C20: =Profitability!K10 -> 551713.5 | D20: =Profitability!L10 -> 0.12244509
B21: =Profitability!B11 -> M35 | C21: =Profitability!K11 -> 290043 | D21: =Profitability!L11 -> 0.12281303
B22: =Profitability!B12 -> M40 | C22: =Profitability!K12 -> 202785 | D22: =Profitability!L12 -> 0.12314741 | F22: SCENARIO — M25 MARGIN
F23: Base | G23: =Scenarios!C21 -> 0.13043478
B24: Highest total PBT: | C24: =INDEX(Profitability!B6:B12,MATCH(MAX(Profitability!K6:K12),Profitability!K6:K12,0)) -> M20 | F24: Downside | G24: =Scenarios!D21 -> 0.021137319
F25: Upside | G25: =Scenarios!E21 -> 0.22432873
B27: (chart data)
B28: =Costing!B6 -> M10 | C28: =Costing!M6 -> 1147.35 | D28: =Profitability!K6 -> 209205 | F28: Cost Split M25
B29: =Costing!B7 -> M15 | C29: =Costing!M7 -> 1205.55 | D29: =Profitability!K7 -> 453330 | F29: Cement | G29: ='Mix Design'!C9*Inputs!D7 -> 2736
B30: =Costing!B8 -> M20 | C30: =Costing!M8 -> 1275.12 | D30: =Profitability!K8 -> 907632 | F30: Sand | G30: ='Mix Design'!D9*Inputs!D8 -> 891
B31: =Costing!B9 -> M25 | C31: =Costing!M9 -> 1322.7525 | D31: =Profitability!K9 -> 785477.25 | F31: Aggregate | G31: =('Mix Design'!E9*Inputs!D9)+('Mix Design'!F9*Inputs!D10) -> 1356.75
B32: =Costing!B10 -> M30 | C32: =Costing!M10 -> 1369.5225 | D32: =Profitability!K10 -> 551713.5 | F32: Diesel+Transport | G32: =Costing!D9+Costing!E9 -> 335
B33: =Costing!B11 -> M35 | C33: =Costing!M11 -> 1416.81 | D33: =Profitability!K11 -> 290043 | F33: Elec+Labour+Repairs | G33: =Costing!G9 -> 213
B34: =Costing!B12 -> M40 | C34: =Costing!M12 -> 1463.925 | D34: =Profitability!K12 -> 202785 | F34: Fixed (plant/admin) | G34: =Costing!I9 -> 390

Sheet Inputs
B2: Input Data — Rates & Assumptions
B3: All blue cells are inputs. Every downstream calculation references this sheet.
B5: Material Rates
B6: Material | C6: Unit | D6: Rate (₹)
B7: Cement | C7: per kg | D7: 7.6
B8: Sand | C8: per kg | D8: 1.35
B9: Aggregate (20mm) | C9: per kg | D9: 1.05
B10: Aggregate (10mm) | C10: per kg | D10: 1.15
B11: Admixture | C11: per kg | D11: 95
B12: Water | C12: per litre | D12: 0.1
B14: Operating & Overhead Rates (per CBM unless noted)
B15: Cost Item | C15: Basis | D15: Rate (₹)
B16: Diesel | C16: per CBM (batching+transport) | D16: 95
B17: Electricity | C17: per CBM | D17: 38
B18: Direct Labour | C18: per CBM | D18: 120
B19: Transport | C19: per CBM | D19: 240
B20: Pumping | C20: per CBM (when pumped) | D20: 180
B21: Repairs & Maintenance | C21: per CBM | D21: 55
B24: Monthly Fixed / Semi-Fixed Costs (₹)
B25: Fixed Cost | C25: Amount/Month (₹)
B26: Plant Rent / Depreciation | C26: 850000
B27: Admin & Salaries | C27: 620000
B28: Interest on Capital | C28: 240000
B29: Insurance & Misc | C29: 90000
B30: Total Monthly Fixed Cost | C30: =SUM(C26:C29) -> 1800000
B33: Key Assumptions
B34: Monthly Volume (CBM) | C34: 4000
B35: Target Markup on Cost (%) | C35: 0.15
B36: Pumped Volume (% of total) | C36: 0.6

Sheet Mix Design
B2: Mix Design — Material Quantity per CBM by Grade
B3: Quantities (kg/CBM) per grade. Material cost = qty × rate (from Inputs).
B5: Grade | C5: Cement (kg) | D5: Sand (kg) | E5: Agg 20mm (kg) | F5: Agg 10mm (kg) | G5: Admixture (kg) | H5: Water (l) | I5: Material Cost/CBM (₹)
B6: M10 | C6: 210 | D6: 720 | E6: 780 | F6: 520 | G6: 0 | H6: 180 | I6: =C6*Inputs!$D$7+D6*Inputs!$D$8+E6*Inputs!$D$9+F6*Inputs!$D$10+G6*Inputs!$D$11+H6*Inputs!$D$12 -> 4003
B7: M15 | C7: 260 | D7: 700 | E7: 770 | F7: 510 | G7: 0.6 | H7: 180 | I7: =C7*Inputs!$D$7+D7*Inputs!$D$8+E7*Inputs!$D$9+F7*Inputs!$D$10+G7*Inputs!$D$11+H7*Inputs!$D$12 -> 4391
B8: M20 | C8: 320 | D8: 680 | E8: 760 | F8: 500 | G8: 1.2 | H8: 178 | I8: =C8*Inputs!$D$7+D8*Inputs!$D$8+E8*Inputs!$D$9+F8*Inputs!$D$10+G8*Inputs!$D$11+H8*Inputs!$D$12 -> 4854.8
B9: M25 | C9: 360 | D9: 660 | E9: 750 | F9: 495 | G9: 1.8 | H9: 176 | I9: =C9*Inputs!$D$7+D9*Inputs!$D$8+E9*Inputs!$D$9+F9*Inputs!$D$10+G9*Inputs!$D$11+H9*Inputs!$D$12 -> 5172.35
B10: M30 | C10: 400 | D10: 640 | E10: 740 | F10: 485 | G10: 2.4 | H10: 174 | I10: =C10*Inputs!$D$7+D10*Inputs!$D$8+E10*Inputs!$D$9+F10*Inputs!$D$10+G10*Inputs!$D$11+H10*Inputs!$D$12 -> 5484.15
B11: M35 | C11: 440 | D11: 620 | E11: 730 | F11: 478 | G11: 3 | H11: 172 | I11: =C11*Inputs!$D$7+D11*Inputs!$D$8+E11*Inputs!$D$9+F11*Inputs!$D$10+G11*Inputs!$D$11+H11*Inputs!$D$12 -> 5799.4
B12: M40 | C12: 480 | D12: 600 | E12: 720 | F12: 470 | G12: 3.6 | H12: 170 | I12: =C12*Inputs!$D$7+D12*Inputs!$D$8+E12*Inputs!$D$9+F12*Inputs!$D$10+G12*Inputs!$D$11+H12*Inputs!$D$12 -> 6113.5

Sheet Costing
B2: Costing Engine — Variable & Fixed Cost per CBM
B3: Volume-driven costs (material, diesel, transport, pumping, electricity, labour, repairs) are treated as variable. Only plant, admin and insurance are fixed; interest sits below EBITDA.
B5: Grade | C5: Material Cost/CBM | D5: Diesel/CBM | E5: Transport/CBM | F5: Pumping/CBM (alloc) | G5: Elec+Labour+Repairs/CBM | H5: Variable Cost/CBM | I5: Fixed Cost/CBM | J5: Total Cost/CBM | K5: Selling Price/CBM | L5: Markup % | M5: Contribution/CBM | N5: Gross Margin %
B6: M10 | C6: ='Mix Design'!I6 -> 4003 | D6: =Inputs!$D$16 -> 95 | E6: =Inputs!$D$19 -> 240 | F6: =Inputs!$D$20*Inputs!$C$36 -> 108 | G6: =Inputs!$D$17+Inputs!$D$18+Inputs!$D$21 -> 213 | H6: =C6+D6+E6+F6+G6 -> 4659 | I6: =(Inputs!$C$30-Inputs!$C$28)/Inputs!$C$34 -> 390 | J6: =H6+I6 -> 5049 | K6: =J6*(1+Inputs!$C$35) -> 5806.35 | L6: =IFERROR((K6-J6)/J6,0) -> 0.15 | M6: =K6-H6 -> 1147.35 | N6: =IFERROR((K6-J6)/K6,0) -> 0.13043478
B7: M15 | C7: ='Mix Design'!I7 -> 4391 | D7: =Inputs!$D$16 -> 95 | E7: =Inputs!$D$19 -> 240 | F7: =Inputs!$D$20*Inputs!$C$36 -> 108 | G7: =Inputs!$D$17+Inputs!$D$18+Inputs!$D$21 -> 213 | H7: =C7+D7+E7+F7+G7 -> 5047 | I7: =(Inputs!$C$30-Inputs!$C$28)/Inputs!$C$34 -> 390 | J7: =H7+I7 -> 5437 | K7: =J7*(1+Inputs!$C$35) -> 6252.55 | L7: =IFERROR((K7-J7)/J7,0) -> 0.15 | M7: =K7-H7 -> 1205.55 | N7: =IFERROR((K7-J7)/K7,0) -> 0.13043478
B8: M20 | C8: ='Mix Design'!I8 -> 4854.8 | D8: =Inputs!$D$16 -> 95 | E8: =Inputs!$D$19 -> 240 | F8: =Inputs!$D$20*Inputs!$C$36 -> 108 | G8: =Inputs!$D$17+Inputs!$D$18+Inputs!$D$21 -> 213 | H8: =C8+D8+E8+F8+G8 -> 5510.8 | I8: =(Inputs!$C$30-Inputs!$C$28)/Inputs!$C$34 -> 390 | J8: =H8+I8 -> 5900.8 | K8: =J8*(1+Inputs!$C$35) -> 6785.92 | L8: =IFERROR((K8-J8)/J8,0) -> 0.15 | M8: =K8-H8 -> 1275.12 | N8: =IFERROR((K8-J8)/K8,0) -> 0.13043478
B9: M25 | C9: ='Mix Design'!I9 -> 5172.35 | D9: =Inputs!$D$16 -> 95 | E9: =Inputs!$D$19 -> 240 | F9: =Inputs!$D$20*Inputs!$C$36 -> 108 | G9: =Inputs!$D$17+Inputs!$D$18+Inputs!$D$21 -> 213 | H9: =C9+D9+E9+F9+G9 -> 5828.35 | I9: =(Inputs!$C$30-Inputs!$C$28)/Inputs!$C$34 -> 390 | J9: =H9+I9 -> 6218.35 | K9: =J9*(1+Inputs!$C$35) -> 7151.1025 | L9: =IFERROR((K9-J9)/J9,0) -> 0.15 | M9: =K9-H9 -> 1322.7525 | N9: =IFERROR((K9-J9)/K9,0) -> 0.13043478
B10: M30 | C10: ='Mix Design'!I10 -> 5484.15 | D10: =Inputs!$D$16 -> 95 | E10: =Inputs!$D$19 -> 240 | F10: =Inputs!$D$20*Inputs!$C$36 -> 108 | G10: =Inputs!$D$17+Inputs!$D$18+Inputs!$D$21 -> 213 | H10: =C10+D10+E10+F10+G10 -> 6140.15 | I10: =(Inputs!$C$30-Inputs!$C$28)/Inputs!$C$34 -> 390 | J10: =H10+I10 -> 6530.15 | K10: =J10*(1+Inputs!$C$35) -> 7509.6725 | L10: =IFERROR((K10-J10)/J10,0) -> 0.15 | M10: =K10-H10 -> 1369.5225 | N10: =IFERROR((K10-J10)/K10,0) -> 0.13043478
B11: M35 | C11: ='Mix Design'!I11 -> 5799.4 | D11: =Inputs!$D$16 -> 95 | E11: =Inputs!$D$19 -> 240 | F11: =Inputs!$D$20*Inputs!$C$36 -> 108 | G11: =Inputs!$D$17+Inputs!$D$18+Inputs!$D$21 -> 213 | H11: =C11+D11+E11+F11+G11 -> 6455.4 | I11: =(Inputs!$C$30-Inputs!$C$28)/Inputs!$C$34 -> 390 | J11: =H11+I11 -> 6845.4 | K11: =J11*(1+Inputs!$C$35) -> 7872.21 | L11: =IFERROR((K11-J11)/J11,0) -> 0.15 | M11: =K11-H11 -> 1416.81 | N11: =IFERROR((K11-J11)/K11,0) -> 0.13043478
B12: M40 | C12: ='Mix Design'!I12 -> 6113.5 | D12: =Inputs!$D$16 -> 95 | E12: =Inputs!$D$19 -> 240 | F12: =Inputs!$D$20*Inputs!$C$36 -> 108 | G12: =Inputs!$D$17+Inputs!$D$18+Inputs!$D$21 -> 213 | H12: =C12+D12+E12+F12+G12 -> 6769.5 | I12: =(Inputs!$C$30-Inputs!$C$28)/Inputs!$C$34 -> 390 | J12: =H12+I12 -> 7159.5 | K12: =J12*(1+Inputs!$C$35) -> 8233.425 | L12: =IFERROR((K12-J12)/J12,0) -> 0.15 | M12: =K12-H12 -> 1463.925 | N12: =IFERROR((K12-J12)/K12,0) -> 0.13043478

Sheet Scenarios
B2: Pricing Scenarios — Sensitivity Analysis
B3: Change the blue shock inputs to test cost, price and volume sensitivity. Base, Downside and Upside update automatically (M25 as reference grade).
B5: Scenario Shock Inputs
B6: Shock | C6: Applied %
B7: Cement price change % | C7: 0.1
B8: Diesel price change % | C8: 0.1
B9: Transport change % | C9: 0.15
B10: Selling price change % | C10: -0.05
B11: Volume change % | C11: -0.2
B14: M25 Sensitivity — Impact per CBM
B15: Metric | C15: Base Case | D15: Downside | E15: Upside
B16: Variable Cost/CBM | C16: =Costing!H9 -> 5828.35 | D16: =C16+'Mix Design'!C9*Inputs!$D$7*C7+Inputs!$D$16*C8+Inputs!$D$19*C9 -> 6147.45 | E16: =C16-'Mix Design'!C9*Inputs!$D$7*C7-Inputs!$D$16*C8-Inputs!$D$19*C9 -> 5509.25
B17: Fixed Cost/CBM | C17: =Costing!I9 -> 390 | D17: =Inputs!$C$30/(Inputs!$C$34*(1+C11))+(Costing!I9-Inputs!$C$30/Inputs!$C$34) -> 502.5 | E17: =Inputs!$C$30/(Inputs!$C$34*(1-C11))+(Costing!I9-Inputs!$C$30/Inputs!$C$34) -> 315
B18: Total Cost/CBM | C18: =C16+C17 -> 6218.35 | D18: =D16+D17 -> 6649.95 | E18: =E16+E17 -> 5824.25
B19: Selling Price/CBM | C19: =Costing!K9 -> 7151.1025 | D19: =C19*(1+C10) -> 6793.5474 | E19: =C19*(1-C10) -> 7508.6576
B20: Contribution/CBM | C20: =C19-C16 -> 1322.7525 | D20: =D19-D16 -> 646.09737 | E20: =E19-E16 -> 1999.4076
B21: Gross Margin % | C21: =IFERROR((C19-C18)/C19,0) -> 0.13043478 | D21: =IFERROR((D19-D18)/D19,0) -> 0.021137319 | E21: =IFERROR((E19-E18)/E19,0) -> 0.22432873

Sheet Profitability
B2: Profitability by Grade (Monthly)
B3: Uses an illustrative monthly sales mix totalling 4,000 CBM. Revenue → Contribution → EBITDA → PBT. Volume mix is an assumption — change it to test product-mix profitability.
B5: Grade | C5: Volume (CBM) | D5: Price/CBM | E5: Revenue | F5: Variable Cost | G5: Contribution | H5: Fixed Cost | I5: EBITDA | J5: Interest | K5: PBT | L5: Margin %
B6: M10 | C6: 300 | D6: =Costing!K6 -> 5806.35 | E6: =C6*D6 -> 1741905 | F6: =C6*Costing!H6 -> 1397700 | G6: =E6-F6 -> 344205 | H6: =C6*(Inputs!$C$30-Inputs!$C$28)/Inputs!$C$34 -> 117000 | I6: =G6-H6 -> 227205 | J6: =C6*Inputs!$C$28/Inputs!$C$34 -> 18000 | K6: =I6-J6 -> 209205 | L6: =IFERROR(K6/E6,0) -> 0.12010127
B7: M15 | C7: 600 | D7: =Costing!K7 -> 6252.55 | E7: =C7*D7 -> 3751530 | F7: =C7*Costing!H7 -> 3028200 | G7: =E7-F7 -> 723330 | H7: =C7*(Inputs!$C$30-Inputs!$C$28)/Inputs!$C$34 -> 234000 | I7: =G7-H7 -> 489330 | J7: =C7*Inputs!$C$28/Inputs!$C$34 -> 36000 | K7: =I7-J7 -> 453330 | L7: =IFERROR(K7/E7,0) -> 0.1208387
B8: M20 | C8: 1100 | D8: =Costing!K8 -> 6785.92 | E8: =C8*D8 -> 7464512 | F8: =C8*Costing!H8 -> 6061880 | G8: =E8-F8 -> 1402632 | H8: =C8*(Inputs!$C$30-Inputs!$C$28)/Inputs!$C$34 -> 429000 | I8: =G8-H8 -> 973632 | J8: =C8*Inputs!$C$28/Inputs!$C$34 -> 66000 | K8: =I8-J8 -> 907632 | L8: =IFERROR(K8/E8,0) -> 0.12159295
B9: M25 | C9: 900 | D9: =Costing!K9 -> 7151.1025 | E9: =C9*D9 -> 6435992.2 | F9: =C9*Costing!H9 -> 5245515 | G9: =E9-F9 -> 1190477.2 | H9: =C9*(Inputs!$C$30-Inputs!$C$28)/Inputs!$C$34 -> 351000 | I9: =G9-H9 -> 839477.25 | J9: =C9*Inputs!$C$28/Inputs!$C$34 -> 54000 | K9: =I9-J9 -> 785477.25 | L9: =IFERROR(K9/E9,0) -> 0.12204447
B10: M30 | C10: 600 | D10: =Costing!K10 -> 7509.6725 | E10: =C10*D10 -> 4505803.5 | F10: =C10*Costing!H10 -> 3684090 | G10: =E10-F10 -> 821713.5 | H10: =C10*(Inputs!$C$30-Inputs!$C$28)/Inputs!$C$34 -> 234000 | I10: =G10-H10 -> 587713.5 | J10: =C10*Inputs!$C$28/Inputs!$C$34 -> 36000 | K10: =I10-J10 -> 551713.5 | L10: =IFERROR(K10/E10,0) -> 0.12244509
B11: M35 | C11: 300 | D11: =Costing!K11 -> 7872.21 | E11: =C11*D11 -> 2361663 | F11: =C11*Costing!H11 -> 1936620 | G11: =E11-F11 -> 425043 | H11: =C11*(Inputs!$C$30-Inputs!$C$28)/Inputs!$C$34 -> 117000 | I11: =G11-H11 -> 308043 | J11: =C11*Inputs!$C$28/Inputs!$C$34 -> 18000 | K11: =I11-J11 -> 290043 | L11: =IFERROR(K11/E11,0) -> 0.12281303
B12: M40 | C12: 200 | D12: =Costing!K12 -> 8233.425 | E12: =C12*D12 -> 1646685 | F12: =C12*Costing!H12 -> 1353900 | G12: =E12-F12 -> 292785 | H12: =C12*(Inputs!$C$30-Inputs!$C$28)/Inputs!$C$34 -> 78000 | I12: =G12-H12 -> 214785 | J12: =C12*Inputs!$C$28/Inputs!$C$34 -> 12000 | K12: =I12-J12 -> 202785 | L12: =IFERROR(K12/E12,0) -> 0.12314741
B13: TOTAL | C13: =SUM(C6:C12) -> 4000 | E13: =SUM(E6:E12) -> 27908091 | F13: =SUM(F6:F12) -> 22707905 | G13: =SUM(G6:G12) -> 5200185.7 | H13: =SUM(H6:H12) -> 1560000 | I13: =SUM(I6:I12) -> 3640185.7 | J13: =SUM(J6:J12) -> 240000 | K13: =SUM(K6:K12) -> 3400185.7 | L13: =IFERROR(K13/E13,0) -> 0.12183513

Sheet working
A1: RMC PRICE CALCULATOR · Per Cubic Meter (CBM)
A2: ⚡ Blue = Change these inputs | Black = Auto-calculated | Green = Final selling price
A4: SECTION 1 · VARIABLE COST INPUTS | G4: SECTION 3A · FIXED COSTS (Monthly)
A5: Material | B5: ⚠ ILLUSTRATIVE / SAMPLE DATA built to demonstrate methodology. All names, figures and values are fictional and do not represent any real company or client. | C5: Unit | D5: Qty/CBM ref | G5: Cost Item | H5: Monthly (₹)
A6: Cement | B6: 6 | C6: ₹/Kg | D6: M10:200 M15:260 | E6: M20:300 M25:320 | G6: Driver Salary (×3 drivers) | H6: 81000
A7: Sand | B7: 1 | C7: ₹/Kg | D7: M10:850 M15:760 | E7: M20:860 M25:850 | G7: Plant Operator | H7: 28000
A8: Jelly | B8: 1 | C8: ₹/Kg | D8: M10:1110 M15:1140 | E8: M20:1110 M25:1110 | G8: Plant Incharge | H8: 30000
A9: Admixture | B9: 96 | C9: ₹/Kg | D9: M10:1.3 M15:1.4 | E9: M20:1.6 M25:1.7 | G9: Plant Helper | H9: 18000
A10: Variable Cost Item | B10: Value | C10: Unit | D10: Note | G10: Rent for Plant | H10: 30000
A11: Diesel per Load (Generator) | B11: 3.5 | C11: Litres | D11: Per 7.5 CBM load | G11: Electricity (Fixed) | H11: 2000
A12: CBM per Load (Transit Mixer) | B12: 7.5 | C12: CBM | D12: Standard TM capacity | G12: Repairs & Maintenance | H12: 25000
A13: Diesel Price | B13: 98 | C13: ₹/Litre | D13: Update when fuel prices change | G13: Pump (Fixed) | H13: 50000
A14: → Diesel Cost per CBM | B14: =ROUND((B11*B13)/B12,2) -> 45.73 | C14: ₹/CBM | D14: Auto-calculated | G14: Contingency (~5%) | H14: 10000
A15: TM Transport Charge | B15: 65 | C15: ₹/CBM | D15: Internal — plant to site & back | G15: Fixed Cost (excl. EMIs) | H15: =SUM(H6:H14) -> 274000
A16: JCB Material Handling | B16: 45 | C16: ₹/CBM | D16: Loading materials into plant
A17: Electricity (Variable) | B17: 5 | C17: ₹/CBM | D17: Variable portion of bill | G17: SECTION 3B · LOAN EMIs (Monthly)
A18: TOTAL OTHER VARIABLE COST | B18: =ROUND(B14+B15+B16+B17,2) -> 160.73 | C18: ₹/CBM | D18: Same across all grades | G18: Loan | H18: EMI (₹/month)
G19: Pump Loan | H19: 54507
A20: SECTION 2 · TOTAL COST SUMMARY (₹ per CBM) | G20: Mixer Loan | H20: 87110
A21: Cost Component | B21: M10 | C21: M15 | D21: M20 | E21: M25 | G21: Generator Loan | H21: 16815
A22: Raw Material Cost (₹/CBM) | B22: =ROUND(B6*200+B7*850+B8*1110+B9*1.3,2) -> 3284.8 | C22: =ROUND(B6*260+B7*760+B8*1140+B9*1.4,2) -> 3594.4 | D22: =ROUND(B6*300+B7*860+B8*1110+B9*1.6,2) -> 3923.6 | E22: =ROUND(B6*320+B7*850+B8*1110+B9*1.7,2) -> 4043.2 | G22: JCB Loan | H22: 0
A23: Other Variable Cost (₹/CBM) | B23: =B18 -> 160.73 | C23: =B18 -> 160.73 | D23: =B18 -> 160.73 | E23: =B18 -> 160.73 | G23: TM I Loan | H23: 0
A24: Fixed Cost per CBM (from right →) | B24: =$H$39 -> 1336.54 | C24: =$H$39 -> 1336.54 | D24: =$H$39 -> 1336.54 | E24: =$H$39 -> 1336.54 | G24: TM II Loan | H24: 102185
A25: TOTAL COST (₹/CBM) | B25: =ROUND(B22+B23+B24,2) -> 4782.07 | C25: =ROUND(C22+C23+C24,2) -> 5091.67 | D25: =ROUND(D22+D23+D24,2) -> 5420.87 | E25: =ROUND(E22+E23+E24,2) -> 5540.47 | G25: Total EMIs | H25: =SUM(H19:H24) -> 260617
A27: SECTION 3 · SELLING PRICE | G27: SECTION 3C · PUMP COST (Monthly)
B28: M10 | C28: M15 | D28: M20 | E28: M25 | G28: Pump Monthly Fixed Cost | H28: 50000
A29: Target Profit Margin (%) | B29: 0.1 | C29: 0.1 | D29: 0.1 | E29: 0.1 | G29: Pump Charge Threshold | H29: 30
A30: SELLING PRICE (₹/CBM) | B30: =ROUND(B25*(1+B29),0) -> 5260 | C30: =ROUND(C25*(1+C29),0) -> 5601 | D30: =ROUND(D25*(1+D29),0) -> 5963 | E30: =ROUND(E25*(1+E29),0) -> 6095 | G30: Small-Order Pump Charge | H30: 10000
A31: Profit per CBM (₹) | B31: =ROUND(B30-B25,2) -> 477.93 | C31: =ROUND(C30-C25,2) -> 509.33 | D31: =ROUND(D30-D25,2) -> 542.13 | E31: =ROUND(E30-E25,2) -> 554.53 | G31: Est. Pump Orders/Month | H31: 15
A32: Est. Monthly Profit (÷4 grades equally) | B32: =ROUND(B31*$H$38/4,0) -> 47793 | C32: =ROUND(C31*$H$38/4,0) -> 50933 | D32: =ROUND(D31*$H$38/4,0) -> 54213 | E32: =ROUND(E31*$H$38/4,0) -> 55453 | G32: % of Pump Orders < Threshold | H32: 0.4
G33: → Monthly Recovery from Small Orders | H33: =ROUND(H31*H32*H30,0) -> 60000
G34: → Net Pump Cost (after recovery) | H34: =MAX(H28-H33,0) -> 0
G36: TOTAL FIXED COST (Monthly) | H36: =H15+H25 -> 534617
G38: Expected Monthly Volume | H38: 400
G39: → Fixed Cost per CBM | H39: =ROUND(H36/H38,2) -> 1336.54
G41: HOW THE PUMP WORKS
G42: ₹50k/month covers pump labour, diesel & transit.
G43: Small orders (<30 CBM): client pays ₹10k → partial recovery.
G44: Large orders (≥30 CBM): pump is free to client.
G45: Net pump cost is absorbed into your fixed cost per CBM.
...
